<?xml version="1.0"?>
<robot name="trucon_robot">
<link name="base_link">
  <visual>
    <geometry>
      <box size="0.2 0.15 0.3"/>
    </geometry>
    <material name="white">
      <color rgba="1 1 1 1"/>
    </material>
  </visual>
  <collision>
    <geometry>
      <box size="0.2 0.15 0.3"/>
    </geometry>
  </collision>
  <inertial>
    <mass value="2.0"/>
    <inertia ixx="0.1" iyy="0.1" izz="0.1"
             ixy="0" ixz="0" iyz="0"/>
  </inertial>
</link>
<link name="neck_link">
  <visual>
    <geometry>
      <cylinder radius="0.03" length="0.1"/>
    </geometry>
    <material name="gray">
      <color rgba="0.5 0.5 0.5 1"/>
    </material>
  </visual>
  <collision>
    <geometry>
      <cylinder radius="0.03" length="0.1"/>
    </geometry>
  </collision>
  <inertial>
    <mass value="0.3"/>
    <inertia ixx="0.01" iyy="0.01" izz="0.01"
             ixy="0" ixz="0" iyz="0"/>
  </inertial>
</link>
<joint name="neck_joint" type="revolute">
    <parent link="base_link"/>
    <child link="neck_link"/>
    <origin xyz="0 0 0.2" rpy="0 0 0"/>
    <axis xyz="1 0 0"/>
    <limit lower="-0.5" upper="0.5" effort="10" velocity="1"/>
  </joint>
<link name="head_link">
  <visual>
    <geometry>
      <sphere radius="0.08"/>
    </geometry>
    <material name="blue">
      <color rgba="0 0 1 1"/>
    </material>
  </visual>
  <collision>
    <geometry>
      <sphere radius="0.08"/>
    </geometry>
  </collision>
  <inertial>
    <mass value="0.5"/>
    <inertia ixx="0.005" iyy="0.005" izz="0.005"
             ixy="0" ixz="0" iyz="0"/>
  </inertial>
</link>
<joint name="head_joint" type="revolute">
    <parent link="neck_link"/>
    <child link="head_link"/>
    <origin xyz="0 0 0.1" rpy="0 0 0"/>
    <axis xyz="0 0 1"/>
    <limit lower="-1.0" upper="1.0" effort="10" velocity="1"/>
  </joint>
<link name="camera_link">
  <visual>
    <geometry>
      <box size="0.04 0.04 0.04"/>
    </geometry>
    <material name="black">
      <color rgba="0 0 0 1"/>
    </material>
  </visual>
  <collision>
    <geometry>
      <box size="0.04 0.04 0.04"/>
    </geometry>
  </collision>
</link>

<joint name="camera_joint" type="fixed">
  <parent link="head_link"/>
  <child link="camera_link"/>
  <origin xyz="0 0.05 0" rpy="0 0 0"/>
</joint>
<link name="right_arm_link">
  <visual>
    <geometry>
      <cylinder radius="0.02" length="0.3"/>
    </geometry>
    <material name="red">
      <color rgba="1 0 0 1"/>
    </material>
  </visual>
  <collision>
    <geometry>
      <cylinder radius="0.02" length="0.3"/>
    </geometry>
  </collision>
  <inertial>
    <mass value="0.5"/>
    <inertia ixx="0.005" iyy="0.005" izz="0.005"
             ixy="0" ixz="0" iyz="0"/>
  </inertial>
</link>
<joint name="right_arm_joint" type="revolute">
  <parent link="base_link"/>
  <child link="right_arm_link"/>
  <origin xyz="0.1 0 0.15" rpy="0 0 0"/>
  <axis xyz="0 1 0"/>
  <limit lower="-1.57" upper="1.57" effort="10" velocity="1"/>
</joint>
<link name="left_arm_link">
  <visual>
    <geometry>
      <cylinder radius="0.02" length="0.3"/>
    </geometry>
    <material name="green">
      <color rgba="0 1 0 1"/>
    </material>
  </visual>
  <collision>
    <geometry>
      <cylinder radius="0.02" length="0.3"/>
    </geometry>
  </collision>
  <inertial>
    <mass value="0.5"/>
    <inertia ixx="0.005" iyy="0.005" izz="0.005"
             ixy="0" ixz="0" iyz="0"/>
  </inertial>
</link>
<joint name="left_arm_joint" type="revolute">
  <parent link="base_link"/>
  <child link="left_arm_link"/>
  <origin xyz="-0.1 0 0.15" rpy="0 0 0"/>
  <axis xyz="0 1 0"/>
  <limit lower="-1.57" upper="1.57" effort="10" velocity="1"/>
</joint><!-- Right Wheel -->
  <link name="right_wheel_link">
    <visual>
      <geometry>
        <cylinder radius="0.05" length="0.04"/>
      </geometry>
      <material name="dark_gray">
        <color rgba="0.2 0.2 0.2 1"/>
      </material>
    </visual>
    <collision>
      <geometry>
        <cylinder radius="0.05" length="0.04"/>
      </geometry>
    </collision>
    <inertial>
      <mass value="0.3"/>
      <inertia ixx="0.001" iyy="0.001" izz="0.001"
               ixy="0" ixz="0" iyz="0"/>
    </inertial>
  </link>

  <joint name="right_wheel_joint" type="continuous">
    <parent link="base_link"/>
    <child link="right_wheel_link"/>
    <origin xyz="0.1 0 -0.1" rpy="0 1.5708 0"/>
    <axis xyz="0 1 0"/>
  </joint>

  <!-- Left Wheel -->
  <link name="left_wheel_link">
    <visual>
      <geometry>
        <cylinder radius="0.05" length="0.04"/>
      </geometry>
      <material name="dark_gray2">
        <color rgba="0.2 0.2 0.2 1"/>
      </material>
    </visual>
    <collision>
      <geometry>
        <cylinder radius="0.05" length="0.04"/>
      </geometry>
    </collision>
    <inertial>
      <mass value="0.3"/>
      <inertia ixx="0.001" iyy="0.001" izz="0.001"
               ixy="0" ixz="0" iyz="0"/>
    </inertial>
  </link>

  <joint name="left_wheel_joint" type="continuous">
    <parent link="base_link"/>
    <child link="left_wheel_link"/>
    <origin xyz="-0.1 0.0 -0.1" rpy="0 1.5708 0"/>
    <axis xyz="0 0 1"/>
  </joint>

<!-- Differential Drive Plugin -->
  <gazebo>
    <plugin name="diff_drive" filename="libgazebo_ros_diff_drive.so">
      <ros>
        <remapping>cmd_vel:=/cmd_vel</remapping>
        <remapping>odom:=/odom</remapping>
      </ros>
      <left_joint>left_wheel_joint</left_joint>
      <right_joint>right_wheel_joint</right_joint>
      <wheel_separation>0.2</wheel_separation>
      <wheel_diameter>0.1</wheel_diameter>
      <max_wheel_torque>20</max_wheel_torque>
      <max_wheel_acceleration>1.0</max_wheel_acceleration>
      <publish_odom>true</publish_odom>
      <publish_odom_tf>true</publish_odom_tf>
      <publish_wheel_tf>true</publish_wheel_tf>
    </plugin>
  </gazebo>
<!-- Camera Sensor -->
  <gazebo reference="camera_link">
    <sensor type="camera" name="head_camera">
      <update_rate>30.0</update_rate>
      <camera name="head">
        <horizontal_fov>1.3962634</horizontal_fov>
        <image>
          <width>640</width>
          <height>480</height>
          <format>R8G8B8</format>
        </image>
        <clip>
          <near>0.02</near>
          <far>300</far>
        </clip>
      </camera>
      <plugin name="camera_controller" filename="libgazebo_ros_camera.so">
        <ros>
          <remapping>image_raw:=/camera/image_raw</remapping>
        </ros>
        <camera_name>head_camera</camera_name>
        <frame_name>camera_link</frame_name>
      </plugin>
    </sensor>
  </gazebo>

  <!-- IMU Sensor -->
  <gazebo reference="base_link">
    <sensor type="imu" name="imu_sensor">
      <update_rate>100.0</update_rate>
      <plugin name="imu_plugin" filename="libgazebo_ros_imu_sensor.so">
        <ros>
          <remapping>~/out:=/imu/data</remapping>
        </ros>
        <initial_orientation_as_reference>false</initial_orientation_as_reference>
      </plugin>
    </sensor>
  </gazebo>

  <!-- Proximity Sensor -->
  <gazebo reference="head_link">
    <sensor type="ray" name="proximity_sensor">
      <update_rate>10.0</update_rate>
      <ray>
        <scan>
          <horizontal>
            <samples>1</samples>
            <resolution>1</resolution>
            <min_angle>0</min_angle>
            <max_angle>0</max_angle>
          </horizontal>
        </scan>
        <range>
          <min>0.02</min>
          <max>2.0</max>
          <resolution>0.01</resolution>
        </range>
      </ray>
      <plugin name="proximity_plugin" filename="libgazebo_ros_ray_sensor.so">
        <ros>
          <remapping>~/out:=/proximity/range</remapping>
        </ros>
        <output_type>sensor_msgs/Range</output_type>
        <frame_name>head_link</frame_name>
      </plugin>
    </sensor>
  </gazebo>
</robot>